<?xml version="1.0"?>
<robot xmlns:xacro="http://www.ros.org/wiki/xacro">

    <material name="white"> 
        <color rgba="1 1 1 1" />
    </material>

    <material name="orange"> 
        <color rgba="1 0.3 0.1 1" />
    </material>

    <material name="blue"> 
        <color rgba="0.2 0.2 1 1" />
    </material>

    <material name="black"> 
        <color rgba="0 0 0 1" />
    </material>

    <!-- BASE LINK -->

    <link name="base_link"> 
        
    </link>

    <!-- CHASSIS LINK -->
    <joint name="chassis_joint" type="fixed"> 
        <parent link="base_link"/>
        <child link="chassis" />
        <!-- set the origin of the joint to behind the base link by 0.1-->
        <origin xyz="-0.1 0 0"/>
    </joint>

    <link name="chassis"> 
        <visual>
            <!-- by default the origin is at the center so we need to move it-->
            <origin xyz="0.15 0 0.075"/>
            <geometry>
                <box size="0.3 0.3 0.15"/>
            </geometry>
            <material name="white"/>
        </visual>
    </link>

    <!-- LEFT WHEEL LINK-->

    <joint name="left_wheel_joint" type="continuous">
        <parent link="base_link"/>
        <child link="left_wheel"/>
        <origin xyz="0 0.175 0" rpy="-${pi/2} 0 0" />
        <!-- Axis of rotation -->
        <axis xyz="0 0 1"/>
    </joint>

    <link name="left_wheel">
        <visual>
            <geometry>
                <cylinder radius="0.05" length="0.04"/>
            </geometry>
            <material name="blue"/>
        </visual>
    </link>


    <!-- RIGHT WHEEL LINK-->

    <joint name="right_wheel_joint" type="continuous">
        <parent link="base_link"/>
        <child link="right_wheel"/>
        <origin xyz="0 -0.175 0" rpy="${pi/2} 0 0" />
        <!-- Axis of rotation -->
        <axis xyz="0 0 -1"/>
    </joint>

    <link name="right_wheel">
        <visual>
            <geometry>
                <cylinder radius="0.05" length="0.04"/>
            </geometry>
            <material name="blue"/>
        </visual>
    </link>

</robot> 